<?xml version="1.0" ?>

<robot name="two_wheel_robot">
  <link name="base_dummy">
  </link>

  <joint name="base_link_joint" type="fixed">
    <origin rpy="0 0 0" xyz="0 0 0"/>
    <parent link="base_dummy"/>
    <child link="Chassis"/>
  </joint>

  <link name="Chassis">
    <inertial>
      <origin rpy="0 0 0" xyz="0 0 0"/>
      <mass value="0.388"/>
      <inertia ixx="0.001787" ixy="0" ixz="0" iyy="0.000979" iyz="0" izz="0.001172"/>
    </inertial>
    <collision>
      <geometry>
        <box size="0.075 0.175 0.157"/>
      </geometry>
      <origin rpy="0 0 0" xyz="0 0 0"/>
    </collision>
    <visual>
      <geometry>
        <box size = "0.075 0.175 0.157"/>
      </geometry>
      <origin rpy="0 0 0" xyz="0 0 0"/> 
    </visual>
  </link>

  <link name="Right_Wheel">
    <inertial>
      <origin rpy="0 0 0" xyz="0 0 0"/>
      <mass value="0.03770"/>
      <inertia ixx="0.000013712" ixy="0" ixz="0" iyy="0.000018823" iyz="0" izz="0.000013712"/>
    </inertial>
    <collision>
      <geometry>
        <cylinder length="0.037" radius="0.0316"/>
      </geometry>
      <origin rpy="1.5708 0 0" xyz="0 0 0"/>
    </collision>
    <visual>
      <geometry>
        <cylinder length="0.037" radius="0.0316"/>
      </geometry>
      <origin rpy="1.5708 0 0" xyz="0 0 0"/>
    </visual>
  </link>

  <joint name="Right_wheel_Joint" type="continuous">
    <parent link="Chassis"/>
    <child link="Right_Wheel"/>
    <origin rpy="0 0 0" xyz="-0.010 0.1075 -0.0785"/>
    <limit effort="100000" velocity="100000"/>
    <axis xyz="0 1 0"/>
  </joint>

  <link name="Left_Wheel">
    <inertial>
      <origin rpy="0 0 0" xyz="0 0 0"/>
      <mass value="0.03770"/>
      <inertia ixx="0.000013712" ixy="0" ixz="0" iyy="0.000018823" iyz="0" izz="0.000013712"/> 
    </inertial>
    <collision>
      <geometry>
        <cylinder length="0.037" radius="0.0316"/>
      </geometry>
      <origin rpy="1.5708 0 0" xyz="0 0 0"/>
    </collision>
    <visual>
      <geometry>
        <cylinder length="0.037" radius="0.0316"/>
      </geometry>
      <origin rpy="1.5708 0 0" xyz="0 0 0"/>
    </visual>
  </link>

  <joint name="Left_wheel_Joint" type="continuous">
    <parent link="Chassis"/>
    <child link="Left_Wheel"/>
    <origin rpy="0 0 0" xyz="-0.010 -0.1075 -0.0785"/>
    <limit effort="100000" velocity="100000"/>
    <axis xyz="0 1 0"/>
  </joint>

  <gazebo reference="Left_Wheel">
    <mu1>0.90</mu1>
    <mu2>0.65</mu2>
    <kp>100000000</kp>
    <kd>10</kd>
    <material>Gazebo/Red</material>
  </gazebo>
  <gazebo reference="Right_Wheel">
    <mu1>0.90</mu1>
    <mu2>0.65</mu2>
    <kp>100000000</kp>
    <kd>10</kd>
    <material>Gazebo/Green</material>
  </gazebo>

  <transmission name="Left_wheel_Trans">
    <type>transmission_interface/SimpleTransmission</type>
    <joint name="Left_wheel_Joint">
      <hardwareInterface>hardware_interface/EffortJointInterface</hardwareInterface>
    </joint>
    <actuator name="Left_wheel_Motor">
      <hardwareInterface>hardware_interface/EffortJointInterface</hardwareInterface>
      <mechanicalReduction>1</mechanicalReduction>
    </actuator>
  </transmission>

  <transmission name="Right_wheel_Trans">
    <type>transmission_interface/SimpleTransmission</type>
    <joint name="Right_wheel_Joint">
      <hardwareInterface>hardware_interface/EffortJointInterface</hardwareInterface>
    </joint>
    <actuator name="Right_wheel_Motor">
      <hardwareInterface>hardware_interface/EffortJointInterface</hardwareInterface>
      <mechanicalReduction>1</mechanicalReduction>
    </actuator>
  </transmission>

  <gazebo>
    <plugin name="gazebo_ros_control" filename="libgazebo_ros_control.so">
      <robotNamespace>/two_wheel_robot</robotNamespace>
    </plugin>
  </gazebo>

  <gazebo>
    <plugin name="imu_plugin" filename="libgazebo_ros_imu.so">
      <alwaysOn>true</alwaysOn>
      <bodyName>Chassis</bodyName>
      <topicName>imu</topicName>
      <serviceName>imu_service</serviceName>
      <gaussianNoise>0.0</gaussianNoise>
      <rpyOffsets>0 0 0</rpyOffsets>
      <accelDrift>0.5 0.5 0.5</accelDrift>
      <accelGaussianNoise>0.35 0.35 0.3</accelGaussianNoise>
      <rateDrift>0.0 0.0 0.0</rateDrift>
      <rateGaussianNoise>0.0 0.0 0.0</rateGaussianNoise>
      <headingDrift>0.0</headingDrift>
      <headingGaussianNoise>0.0</headingGaussianNoise>
      <updateRate>0</updateRate>
    </plugin>
  </gazebo>

  <!--
  <gazebo reference="Chassis">
    <gravity>true</gravity>
    <sensor name="imu_sensor" type="imu">
      <always_on>true</always_on>
      <update_rate>100</update_rate>
      <visualize>true</visualize>
      <topic>__default_topic__</topic>
      <plugin filename="libgazebo_ros_imu_sensor.so" name="imu_plugin">
        <topicName>imu</topicName>
        <bodyName>Chassis</bodyName>
        <updateRateHZ>100.0</updateRateHZ>
        <gaussianNoise>0.0</gaussianNoise>
        <xyzOffset>0 0 0</xyzOffset>
        <rpyOffset>0 0 0</rpyOffset>
        <frameName>Chassis</frameName>
        <initialOrientationAsReference>false</initialOrientationAsReference>
      </plugin>
      <pose>0 0 0 0 0 0</pose>
    </sensor>
  </gazebo>
  -->
</robot>

