<?xml version="1.0" ?>
<!-- =================================================================================== -->
<!-- |    This document was autogenerated by xacro from pendulum.xacro                 | -->
<!-- |    EDITING THIS FILE BY HAND IS NOT RECOMMENDED                                 | -->
<!-- =================================================================================== -->
<robot name="box">
  <joint name="y_joint" type="prismatic">
    <origin rpy="0 0 0" xyz="0 0 1.6 "/>
    <axis xyz="0 1 0"/>
    <parent link="base_link"/>
    <child link="link_box"/>
    <dynamics damping="0.00"/>
    <limit lower="-10" upper="10" effort="1000" velocity="10"/>
    <safety_controller k_velocity="0"/>
  </joint>
  
  <link name="world"/>
  <link name="base_link">
    <inertial>
      <mass value="1"/>
      <origin rpy="0 0 0" xyz="0 0 0"/>
      <inertia ixx="1" ixy="0.0" ixz="0.0" iyy="1" iyz="0.0" izz="1"/>
    </inertial>
  </link>
  
  <joint name="fixed" type="fixed">
    <parent link="world"/>
    <child link="base_link"/>
  </joint>
  
  
  <link name="link_box">
    <inertial>
      <mass value="1"/>
      <origin rpy="0 0 0" xyz="0 0 0"/>
      <inertia ixx="0.27083333333" ixy="0.0" ixz="0.0" iyy="0.27083333333" iyz="0.0" izz="0.27083333333"/>
      <!--inertia ixx="1/12*1*(1+2.25)" ixy="0.0" ixz="0.0" iyy="1/12*1*(2.25+0.25)" iyz="0.0" izz="1/12*1*(1+0.25)"/-->
    </inertial>
    
    <visual>
      <origin rpy="0 0 0" xyz="0.0 0 0"/>
      <geometry>
        <box size="0.5 1 1.5"/>
      </geometry>
      <material name="Red"/>
    </visual>
    <collision>
      <origin rpy="0 0 0" xyz="0.0 0 0"/>
      <geometry>
        <box size="0.5 1 1.5"/>
      </geometry>
    </collision>
  </link>
  
</robot>

