<?xml version="1.0" ?>
<!-- =================================================================================== -->
<!-- |    This document was autogenerated by xacro from pendulum.xacro                 | -->
<!-- |    EDITING THIS FILE BY HAND IS NOT RECOMMENDED                                 | -->
<!-- =================================================================================== -->
<robot name="pendulum">
  <!--xacro:property name="pi" value="3.14159265359" /-->
  <joint name="pendulum_joint" type="continuous">
    <origin rpy="1.5707963267948966 0 0" xyz="0 0 1.6 "/>
    <axis xyz="0 0 1"/>
    <parent link="base_link"/>
    <child link="link_sphere"/>
    <!--dynamics damping="0.01"/-->
    <dynamics damping="0.00"/>
    <limit effort="1000" velocity="0"/>
    <safety_controller k_velocity="0"/>
  </joint>
  <link name="world"/>
  <link name="base_link">
    <inertial>
      <mass value="1"/>
      <origin rpy="0 0 0" xyz="0 0 0"/>
      <inertia ixx="1" ixy="0.0" ixz="0.0" iyy="1" iyz="0.0" izz="1"/>
    </inertial>
    <!--inertial>
        <mass value="0.00" />
        <origin xyz="0 0 0" rpy="0 0 0" />
        <inertia  ixx="0.00" ixy="0.0" ixz="0.0"
                  iyy="0.00" iyz="0.0"
                  izz="0.00" />
      </inertial-->
  </link>
  <joint name="fixed" type="fixed">
    <parent link="world"/>
    <child link="base_link"/>
  </joint>
  <link name="link_sphere">
    <inertial>
      <mass value="0.1"/>
      <origin rpy="0 0 0" xyz="1.0 0 0"/>
      <inertia ixx="3.5999999999999994e-05" ixy="0.0" ixz="0.0" iyy="3.5999999999999994e-05" iyz="0.0" izz="3.5999999999999994e-05"/>
    </inertial>
    <visual>
      <origin rpy="0 0 0" xyz="1.0 0 0"/>
      <geometry>
        <sphere radius="0.03"/>
      </geometry>
      <material name="Red"/>
    </visual>
    <collision>
      <origin rpy="0 0 0" xyz="1.0 0 0"/>
      <geometry>
        <sphere radius="0.03"/>
      </geometry>
    </collision>
  </link>
  <joint name="fixed_joint_rod_sphere" type="fixed">
    <origin rpy="0 0 0" xyz="0 0 0"/>
    <parent link="link_sphere"/>
    <child link="link_rod"/>
  </joint>
  <link name="link_rod">
    <inertial>
      <mass value="0.01"/>
      <origin rpy="0 0 0" xyz="0 0 0"/>
      <inertia ixx="0.0008335833333333334" ixy="0.0" ixz="0.0" iyy="0.0008335833333333334" iyz="0.0" izz="5.000000000000001e-07"/>
    </inertial>
    <visual>
      <origin rpy="0 1.5707963267948966 0" xyz="0.5 0 0"/>
      <geometry>
        <cylinder length="1.0" radius="0.01"/>
      </geometry>
      <material name="Red"/>
    </visual>
    <collision>
      <origin rpy="0 1.5707963267948966 0" xyz="0.5 0 0"/>
      <geometry>
        <cylinder length="1.0" radius="0.01"/>
      </geometry>
    </collision>
  </link>
</robot>

